Eval num_timesteps=1, episode_reward=67.83 +/- 0.00
Episode length: 176.00 +/- 0.00
New best mean reward!
Traceback (most recent call last):
  File "C:\Users\cymstar_user\AppData\Local\Programs\Python\Python38\lib\site-packages\torch\serialization.py", line 441, in save
    _save(obj, opened_zipfile, pickle_module, pickle_protocol)
  File "C:\Users\cymstar_user\AppData\Local\Programs\Python\Python38\lib\site-packages\torch\serialization.py", line 668, in _save
    zip_file.write_record(name, storage.data_ptr(), num_bytes)
  File "C:\Users\cymstar_user\AppData\Local\Programs\Python\Python38\lib\zipfile.py", line 1104, in write
    data = self._compressor.compress(data)
KeyboardInterrupt
During handling of the above exception, another exception occurred:
Traceback (most recent call last):
  File "loading_main.py", line 110, in <module>
    loaded_model.learn(
  File "C:\Users\cymstar_user\AppData\Local\Programs\Python\Python38\lib\site-packages\stable_baselines3\ppo\ppo.py", line 299, in learn
    return super(PPO, self).learn(
  File "C:\Users\cymstar_user\AppData\Local\Programs\Python\Python38\lib\site-packages\stable_baselines3\common\on_policy_algorithm.py", line 250, in learn
    continue_training = self.collect_rollouts(self.env, callback, self.rollout_buffer, n_rollout_steps=self.n_steps)
  File "C:\Users\cymstar_user\AppData\Local\Programs\Python\Python38\lib\site-packages\stable_baselines3\common\on_policy_algorithm.py", line 184, in collect_rollouts
    if callback.on_step() is False:
  File "C:\Users\cymstar_user\AppData\Local\Programs\Python\Python38\lib\site-packages\stable_baselines3\common\callbacks.py", line 88, in on_step
    return self._on_step()
  File "C:\Users\cymstar_user\AppData\Local\Programs\Python\Python38\lib\site-packages\stable_baselines3\common\callbacks.py", line 192, in _on_step
    continue_training = callback.on_step() and continue_training
  File "C:\Users\cymstar_user\AppData\Local\Programs\Python\Python38\lib\site-packages\stable_baselines3\common\callbacks.py", line 88, in on_step
    return self._on_step()
  File "loading_main.py", line 22, in _on_step
    super()._on_step()
  File "C:\Users\cymstar_user\AppData\Local\Programs\Python\Python38\lib\site-packages\stable_baselines3\common\callbacks.py", line 433, in _on_step
    self.model.save(os.path.join(self.best_model_save_path, "best_model"))
  File "C:\Users\cymstar_user\AppData\Local\Programs\Python\Python38\lib\site-packages\stable_baselines3\common\base_class.py", line 818, in save
    save_to_zip_file(path, data=data, params=params_to_save, pytorch_variables=pytorch_variables)
  File "C:\Users\cymstar_user\AppData\Local\Programs\Python\Python38\lib\site-packages\stable_baselines3\common\save_util.py", line 329, in save_to_zip_file
    th.save(dict_, file)
  File "C:\Users\cymstar_user\AppData\Local\Programs\Python\Python38\lib\site-packages\torch\serialization.py", line 442, in save
    return
  File "C:\Users\cymstar_user\AppData\Local\Programs\Python\Python38\lib\site-packages\torch\serialization.py", line 305, in __exit__
    self.file_like.write_end_of_file()
RuntimeError: [enforce fail at C:\actions-runner\_work\pytorch\pytorch\builder\windows\pytorch\caffe2\serialize\inline_container.cc:337] . unexpected pos 308672 vs 308624