2024-02-07 19:34:37,575 INFO    StreamThr :17860 [internal.py:wandb_internal():86] W&B internal server running at pid: 17860, started at: 2024-02-07 19:34:37.575760
2024-02-07 19:34:37,576 DEBUG   HandlerThread:17860 [handler.py:handle_request():146] handle_request: status
2024-02-07 19:34:37,579 INFO    WriterThread:17860 [datastore.py:open_for_write():85] open: F:\Everything\PPO-based-Autonomous-Navigation-for-Quadcopters\wandb\run-20240207_193437-f40yw5wi\run-f40yw5wi.wandb
2024-02-07 19:34:37,579 DEBUG   SenderThread:17860 [sender.py:send():382] send: header
2024-02-07 19:34:37,604 DEBUG   SenderThread:17860 [sender.py:send():382] send: run
2024-02-07 19:34:37,819 INFO    SenderThread:17860 [dir_watcher.py:__init__():211] watching files in: F:\Everything\PPO-based-Autonomous-Navigation-for-Quadcopters\wandb\run-20240207_193437-f40yw5wi\files
2024-02-07 19:34:37,820 INFO    SenderThread:17860 [sender.py:_start_run_threads():1136] run started: f40yw5wi with start time 1707356077.576759
2024-02-07 19:34:37,824 DEBUG   HandlerThread:17860 [handler.py:handle_request():146] handle_request: check_version
2024-02-07 19:34:37,824 DEBUG   SenderThread:17860 [sender.py:send_request():409] send_request: check_version
2024-02-07 19:34:38,069 DEBUG   HandlerThread:17860 [handler.py:handle_request():146] handle_request: run_start
2024-02-07 19:34:38,095 DEBUG   HandlerThread:17860 [system_info.py:__init__():32] System info init
2024-02-07 19:34:38,095 DEBUG   HandlerThread:17860 [system_info.py:__init__():47] System info init done
2024-02-07 19:34:38,095 INFO    HandlerThread:17860 [system_monitor.py:start():194] Starting system monitor
2024-02-07 19:34:38,096 INFO    SystemMonitor:17860 [system_monitor.py:_start():158] Starting system asset monitoring threads
2024-02-07 19:34:38,096 INFO    HandlerThread:17860 [system_monitor.py:probe():214] Collecting system info
2024-02-07 19:34:38,100 INFO    SystemMonitor:17860 [interfaces.py:start():190] Started cpu monitoring
2024-02-07 19:34:38,100 INFO    SystemMonitor:17860 [interfaces.py:start():190] Started disk monitoring
2024-02-07 19:34:38,101 INFO    SystemMonitor:17860 [interfaces.py:start():190] Started gpu monitoring
2024-02-07 19:34:38,104 INFO    SystemMonitor:17860 [interfaces.py:start():190] Started memory monitoring
2024-02-07 19:34:38,110 INFO    SystemMonitor:17860 [interfaces.py:start():190] Started network monitoring
2024-02-07 19:34:38,133 DEBUG   HandlerThread:17860 [system_info.py:probe():196] Probing system
2024-02-07 19:34:38,134 DEBUG   HandlerThread:17860 [system_info.py:_probe_git():181] Probing git
2024-02-07 19:34:38,173 ERROR   HandlerThread:17860 [gitlib.py:root():92] git root error: Cmd('git') failed due to: exit code(128)
  cmdline: git rev-parse --show-toplevel
  stderr: 'fatal: detected dubious ownership in repository at 'F:/Everything/PPO-based-Autonomous-Navigation-for-Quadcopters'
'F:/Everything/PPO-based-Autonomous-Navigation-for-Quadcopters' is on a file system that does not record ownership
To add an exception for this directory, call:

	git config --global --add safe.directory F:/Everything/PPO-based-Autonomous-Navigation-for-Quadcopters'
2024-02-07 19:34:38,173 DEBUG   HandlerThread:17860 [system_info.py:_probe_git():189] Probing git done
2024-02-07 19:34:38,173 DEBUG   HandlerThread:17860 [system_info.py:probe():244] Probing system done
2024-02-07 19:34:38,173 DEBUG   HandlerThread:17860 [system_monitor.py:probe():223] {'os': 'Windows-10-10.0.22000-SP0', 'python': '3.9.2', 'heartbeatAt': '2024-02-08T01:34:38.133760', 'startedAt': '2024-02-08T01:34:37.446760', 'docker': None, 'cuda': None, 'args': (), 'state': 'running', 'program': 'f:\\Everything\\PPO-based-Autonomous-Navigation-for-Quadcopters\\loading_main.py', 'codePathLocal': 'loading_main.py', 'codePath': 'loading_main.py', 'git': {'remote': 'https://github.com/Samuel-Fipps/airSim_Drone.git', 'commit': None}, 'email': 'samuelfipps@gmail.com', 'root': 'F:\\Everything\\PPO-based-Autonomous-Navigation-for-Quadcopters', 'host': 'DESKTOP-VP5KEII', 'username': '14055', 'executable': 'C:\\Users\\14055\\AppData\\Local\\Programs\\Python\\Python39\\python.exe', 'cpu_count': 16, 'cpu_count_logical': 24, 'cpu_freq': {'current': 3418.0, 'min': 0.0, 'max': 3418.0}, 'cpu_freq_per_core': [{'current': 3418.0, 'min': 0.0, 'max': 3418.0}], 'disk': {'/': {'total': 953.8515625, 'used': 125.684814453125}}, 'gpu': 'NVIDIA GeForce RTX 3090', 'gpu_count': 2, 'gpu_devices': [{'name': 'NVIDIA GeForce RTX 3090', 'memory_total': 25769803776}, {'name': 'NVIDIA GeForce RTX 3090', 'memory_total': 25769803776}], 'memory': {'total': 127.79042434692383}}
2024-02-07 19:34:38,173 INFO    HandlerThread:17860 [system_monitor.py:probe():224] Finished collecting system info
2024-02-07 19:34:38,173 INFO    HandlerThread:17860 [system_monitor.py:probe():227] Publishing system info
2024-02-07 19:34:38,173 DEBUG   HandlerThread:17860 [system_info.py:_save_pip():52] Saving list of pip packages installed into the current environment
2024-02-07 19:34:38,175 DEBUG   HandlerThread:17860 [system_info.py:_save_pip():68] Saving pip packages done
2024-02-07 19:34:38,175 DEBUG   HandlerThread:17860 [system_info.py:_save_code():90] Saving code
2024-02-07 19:34:38,199 ERROR   HandlerThread:17860 [gitlib.py:root():92] git root error: Cmd('git') failed due to: exit code(128)
  cmdline: git rev-parse --show-toplevel
  stderr: 'fatal: detected dubious ownership in repository at 'F:/Everything/PPO-based-Autonomous-Navigation-for-Quadcopters'
'F:/Everything/PPO-based-Autonomous-Navigation-for-Quadcopters' is on a file system that does not record ownership
To add an exception for this directory, call:

	git config --global --add safe.directory F:/Everything/PPO-based-Autonomous-Navigation-for-Quadcopters'
2024-02-07 19:34:38,227 DEBUG   HandlerThread:17860 [system_info.py:_save_code():111] Saving code done
2024-02-07 19:34:38,227 DEBUG   HandlerThread:17860 [system_info.py:_save_patches():128] Saving git patches
2024-02-07 19:34:38,245 ERROR   HandlerThread:17860 [gitlib.py:root():92] git root error: Cmd('git') failed due to: exit code(128)
  cmdline: git rev-parse --show-toplevel
  stderr: 'fatal: detected dubious ownership in repository at 'F:/Everything/PPO-based-Autonomous-Navigation-for-Quadcopters'
'F:/Everything/PPO-based-Autonomous-Navigation-for-Quadcopters' is on a file system that does not record ownership
To add an exception for this directory, call:

	git config --global --add safe.directory F:/Everything/PPO-based-Autonomous-Navigation-for-Quadcopters'
2024-02-07 19:34:38,825 INFO    WriterThread:17860 [datastore.py:close():294] close: F:\Everything\PPO-based-Autonomous-Navigation-for-Quadcopters\wandb\run-20240207_193437-f40yw5wi\run-f40yw5wi.wandb
2024-02-07 19:34:38,826 INFO    Thread-16 :17860 [dir_watcher.py:_on_file_created():271] file/dir created: F:\Everything\PPO-based-Autonomous-Navigation-for-Quadcopters\wandb\run-20240207_193437-f40yw5wi\files\code\loading_main.py
2024-02-07 19:34:38,826 INFO    Thread-16 :17860 [dir_watcher.py:_on_file_created():271] file/dir created: F:\Everything\PPO-based-Autonomous-Navigation-for-Quadcopters\wandb\run-20240207_193437-f40yw5wi\files\requirements.txt
2024-02-07 19:34:38,826 INFO    Thread-16 :17860 [dir_watcher.py:_on_file_created():271] file/dir created: F:\Everything\PPO-based-Autonomous-Navigation-for-Quadcopters\wandb\run-20240207_193437-f40yw5wi\files\code
2024-02-07 19:34:39,079 INFO    SenderThread:17860 [sender.py:finish():1548] shutting down sender
2024-02-07 19:34:39,079 INFO    SenderThread:17860 [dir_watcher.py:finish():358] shutting down directory watcher
2024-02-07 19:34:39,829 INFO    SenderThread:17860 [dir_watcher.py:finish():388] scan: F:\Everything\PPO-based-Autonomous-Navigation-for-Quadcopters\wandb\run-20240207_193437-f40yw5wi\files
2024-02-07 19:34:39,829 INFO    SenderThread:17860 [dir_watcher.py:finish():402] scan save: F:\Everything\PPO-based-Autonomous-Navigation-for-Quadcopters\wandb\run-20240207_193437-f40yw5wi\files\config.yaml config.yaml
2024-02-07 19:34:39,829 INFO    SenderThread:17860 [dir_watcher.py:finish():402] scan save: F:\Everything\PPO-based-Autonomous-Navigation-for-Quadcopters\wandb\run-20240207_193437-f40yw5wi\files\requirements.txt requirements.txt
2024-02-07 19:34:39,831 INFO    SenderThread:17860 [dir_watcher.py:finish():402] scan save: F:\Everything\PPO-based-Autonomous-Navigation-for-Quadcopters\wandb\run-20240207_193437-f40yw5wi\files\code\loading_main.py code/loading_main.py
2024-02-07 19:34:39,832 INFO    SenderThread:17860 [file_pusher.py:finish():175] shutting down file pusher
2024-02-07 19:34:39,832 INFO    SenderThread:17860 [file_pusher.py:join():181] waiting for file pusher
2024-02-07 19:34:40,259 INFO    wandb-upload_2:17860 [upload_job.py:push():131] Uploaded file F:\Everything\PPO-based-Autonomous-Navigation-for-Quadcopters\wandb\run-20240207_193437-f40yw5wi\files\code\loading_main.py
2024-02-07 19:34:40,259 INFO    wandb-upload_0:17860 [upload_job.py:push():131] Uploaded file F:\Everything\PPO-based-Autonomous-Navigation-for-Quadcopters\wandb\run-20240207_193437-f40yw5wi\files\config.yaml
2024-02-07 19:34:40,282 INFO    wandb-upload_1:17860 [upload_job.py:push():131] Uploaded file F:\Everything\PPO-based-Autonomous-Navigation-for-Quadcopters\wandb\run-20240207_193437-f40yw5wi\files\requirements.txt
2024-02-07 19:34:40,842 INFO    SenderThread:17860 [file_stream.py:finish():595] file stream finish called
2024-02-07 19:34:40,960 INFO    SenderThread:17860 [file_stream.py:finish():599] file stream finish is done
2024-02-07 19:34:41,136 ERROR   StreamThr :17860 [internal.py:wandb_internal():174] Thread HandlerThread:
Traceback (most recent call last):
  File "C:\Users\14055\AppData\Local\Programs\Python\Python39\lib\site-packages\wandb\sdk\internal\internal_util.py", line 49, in run
    self._run()
  File "C:\Users\14055\AppData\Local\Programs\Python\Python39\lib\site-packages\wandb\sdk\internal\internal_util.py", line 100, in _run
    self._process(record)
  File "C:\Users\14055\AppData\Local\Programs\Python\Python39\lib\site-packages\wandb\sdk\internal\internal.py", line 279, in _process
    self._hm.handle(record)
  File "C:\Users\14055\AppData\Local\Programs\Python\Python39\lib\site-packages\wandb\sdk\internal\handler.py", line 138, in handle
    handler(record)
  File "C:\Users\14055\AppData\Local\Programs\Python\Python39\lib\site-packages\wandb\sdk\internal\handler.py", line 148, in handle_request
    handler(record)
  File "C:\Users\14055\AppData\Local\Programs\Python\Python39\lib\site-packages\wandb\sdk\internal\handler.py", line 683, in handle_request_run_start
    self._system_monitor.probe(publish=True)
  File "C:\Users\14055\AppData\Local\Programs\Python\Python39\lib\site-packages\wandb\sdk\internal\system\system_monitor.py", line 228, in probe
    self.system_info.publish(system_info)
  File "C:\Users\14055\AppData\Local\Programs\Python\Python39\lib\site-packages\wandb\sdk\internal\system\system_info.py", line 255, in publish
    self._save_patches()
  File "C:\Users\14055\AppData\Local\Programs\Python\Python39\lib\site-packages\wandb\sdk\internal\system\system_info.py", line 146, in _save_patches
    upstream_commit = self.git.get_upstream_fork_point()
  File "C:\Users\14055\AppData\Local\Programs\Python\Python39\lib\site-packages\wandb\sdk\lib\gitlib.py", line 200, in get_upstream_fork_point
    possible_relatives.append(tracking_branch.commit)
  File "C:\Users\14055\AppData\Local\Programs\Python\Python39\lib\site-packages\git\refs\symbolic.py", line 226, in _get_commit
    obj = self._get_object()
  File "C:\Users\14055\AppData\Local\Programs\Python\Python39\lib\site-packages\git\refs\symbolic.py", line 219, in _get_object
    return Object.new_from_sha(self.repo, hex_to_bin(self.dereference_recursive(self.repo, self.path)))
  File "C:\Users\14055\AppData\Local\Programs\Python\Python39\lib\site-packages\git\objects\base.py", line 94, in new_from_sha
    oinfo = repo.odb.info(sha1)
  File "C:\Users\14055\AppData\Local\Programs\Python\Python39\lib\site-packages\git\db.py", line 40, in info
    hexsha, typename, size = self._git.get_object_header(bin_to_hex(binsha))
  File "C:\Users\14055\AppData\Local\Programs\Python\Python39\lib\site-packages\git\cmd.py", line 1383, in get_object_header
    return self.__get_object_header(cmd, ref)
  File "C:\Users\14055\AppData\Local\Programs\Python\Python39\lib\site-packages\git\cmd.py", line 1369, in __get_object_header
    cmd.stdin.flush()
OSError: [Errno 22] Invalid argument
